Workbook

Sheet Test Summary Report
B1: TEST REPORT
B3: Project Name | C3: LAB5 - Kiểm thử (Bài 4,5) | F3: Creator | G3: NguyenHoTruongTam
B4: Group ID | C4: 11CNPM2 - NguyenHoTruongTam | F4: Approver | G4: Giảng viên
B6: Date | C6: 27-01-2026
B9: No. | C9: Items | D9: Tested | E9: Passed | F9: Failed | G9: Blocked | H9: Skipped | I9: Not yet tested | J9: Total | K9: Test Coverage
B10: 1 | C10: B4_TC01 | D10: =IF(OR(B4_TC01!$K$2="Pass",B4_TC01!$K$2="Fail",B4_TC01!$K$2="Blocked",B4_TC01!$K$2="Skipped"),1,0) -> 1 | E10: =IF(B4_TC01!$K$2="Pass",1,0) -> 1 | F10: =IF(B4_TC01!$K$2="Fail",1,0) -> 0 | G10: =IF(B4_TC01!$K$2="Blocked",1,0) -> 0 | H10: =IF(B4_TC01!$K$2="Skipped",1,0) -> 0 | I10: =IF(OR(B4_TC01!$K$2="Not Executed",B4_TC01!$K$2=""),1,0) -> 0 | J10: 1 | K10: =D10/J10 -> 1
B11: 2 | C11: B4_TC02 | D11: =IF(OR(B4_TC02!$K$2="Pass",B4_TC02!$K$2="Fail",B4_TC02!$K$2="Blocked",B4_TC02!$K$2="Skipped"),1,0) -> 1 | E11: =IF(B4_TC02!$K$2="Pass",1,0) -> 1 | F11: =IF(B4_TC02!$K$2="Fail",1,0) -> 0 | G11: =IF(B4_TC02!$K$2="Blocked",1,0) -> 0 | H11: =IF(B4_TC02!$K$2="Skipped",1,0) -> 0 | I11: =IF(OR(B4_TC02!$K$2="Not Executed",B4_TC02!$K$2=""),1,0) -> 0 | J11: 1 | K11: =D11/J11 -> 1
B12: 3 | C12: B4_TC03 | D12: =IF(OR(B4_TC03!$K$2="Pass",B4_TC03!$K$2="Fail",B4_TC03!$K$2="Blocked",B4_TC03!$K$2="Skipped"),1,0) -> 1 | E12: =IF(B4_TC03!$K$2="Pass",1,0) -> 1 | F12: =IF(B4_TC03!$K$2="Fail",1,0) -> 0 | G12: =IF(B4_TC03!$K$2="Blocked",1,0) -> 0 | H12: =IF(B4_TC03!$K$2="Skipped",1,0) -> 0 | I12: =IF(OR(B4_TC03!$K$2="Not Executed",B4_TC03!$K$2=""),1,0) -> 0 | J12: 1 | K12: =D12/J12 -> 1
B13: 4 | C13: B4_TC04 | D13: =IF(OR(B4_TC04!$K$2="Pass",B4_TC04!$K$2="Fail",B4_TC04!$K$2="Blocked",B4_TC04!$K$2="Skipped"),1,0) -> 1 | E13: =IF(B4_TC04!$K$2="Pass",1,0) -> 1 | F13: =IF(B4_TC04!$K$2="Fail",1,0) -> 0 | G13: =IF(B4_TC04!$K$2="Blocked",1,0) -> 0 | H13: =IF(B4_TC04!$K$2="Skipped",1,0) -> 0 | I13: =IF(OR(B4_TC04!$K$2="Not Executed",B4_TC04!$K$2=""),1,0) -> 0 | J13: 1 | K13: =D13/J13 -> 1
B14: 5 | C14: B4_TC05 | D14: =IF(OR(B4_TC05!$K$2="Pass",B4_TC05!$K$2="Fail",B4_TC05!$K$2="Blocked",B4_TC05!$K$2="Skipped"),1,0) -> 1 | E14: =IF(B4_TC05!$K$2="Pass",1,0) -> 1 | F14: =IF(B4_TC05!$K$2="Fail",1,0) -> 0 | G14: =IF(B4_TC05!$K$2="Blocked",1,0) -> 0 | H14: =IF(B4_TC05!$K$2="Skipped",1,0) -> 0 | I14: =IF(OR(B4_TC05!$K$2="Not Executed",B4_TC05!$K$2=""),1,0) -> 0 | J14: 1 | K14: =D14/J14 -> 1
B15: 6 | C15: B4_TC06 | D15: =IF(OR(B4_TC06!$K$2="Pass",B4_TC06!$K$2="Fail",B4_TC06!$K$2="Blocked",B4_TC06!$K$2="Skipped"),1,0) -> 1 | E15: =IF(B4_TC06!$K$2="Pass",1,0) -> 1 | F15: =IF(B4_TC06!$K$2="Fail",1,0) -> 0 | G15: =IF(B4_TC06!$K$2="Blocked",1,0) -> 0 | H15: =IF(B4_TC06!$K$2="Skipped",1,0) -> 0 | I15: =IF(OR(B4_TC06!$K$2="Not Executed",B4_TC06!$K$2=""),1,0) -> 0 | J15: 1 | K15: =D15/J15 -> 1
B16: 7 | C16: B4_TC07 | D16: =IF(OR(B4_TC07!$K$2="Pass",B4_TC07!$K$2="Fail",B4_TC07!$K$2="Blocked",B4_TC07!$K$2="Skipped"),1,0) -> 1 | E16: =IF(B4_TC07!$K$2="Pass",1,0) -> 1 | F16: =IF(B4_TC07!$K$2="Fail",1,0) -> 0 | G16: =IF(B4_TC07!$K$2="Blocked",1,0) -> 0 | H16: =IF(B4_TC07!$K$2="Skipped",1,0) -> 0 | I16: =IF(OR(B4_TC07!$K$2="Not Executed",B4_TC07!$K$2=""),1,0) -> 0 | J16: 1 | K16: =D16/J16 -> 1
B17: 8 | C17: B5_TC01 | D17: =IF(OR(B5_TC01!$K$2="Pass",B5_TC01!$K$2="Fail",B5_TC01!$K$2="Blocked",B5_TC01!$K$2="Skipped"),1,0) -> 1 | E17: =IF(B5_TC01!$K$2="Pass",1,0) -> 1 | F17: =IF(B5_TC01!$K$2="Fail",1,0) -> 0 | G17: =IF(B5_TC01!$K$2="Blocked",1,0) -> 0 | H17: =IF(B5_TC01!$K$2="Skipped",1,0) -> 0 | I17: =IF(OR(B5_TC01!$K$2="Not Executed",B5_TC01!$K$2=""),1,0) -> 0 | J17: 1 | K17: =D17/J17 -> 1
B18: 9 | C18: B5_TC02 | D18: =IF(OR(B5_TC02!$K$2="Pass",B5_TC02!$K$2="Fail",B5_TC02!$K$2="Blocked",B5_TC02!$K$2="Skipped"),1,0) -> 1 | E18: =IF(B5_TC02!$K$2="Pass",1,0) -> 1 | F18: =IF(B5_TC02!$K$2="Fail",1,0) -> 0 | G18: =IF(B5_TC02!$K$2="Blocked",1,0) -> 0 | H18: =IF(B5_TC02!$K$2="Skipped",1,0) -> 0 | I18: =IF(OR(B5_TC02!$K$2="Not Executed",B5_TC02!$K$2=""),1,0) -> 0 | J18: 1 | K18: =D18/J18 -> 1
B19: 10 | C19: B5_TC03 | D19: =IF(OR(B5_TC03!$K$2="Pass",B5_TC03!$K$2="Fail",B5_TC03!$K$2="Blocked",B5_TC03!$K$2="Skipped"),1,0) -> 1 | E19: =IF(B5_TC03!$K$2="Pass",1,0) -> 1 | F19: =IF(B5_TC03!$K$2="Fail",1,0) -> 0 | G19: =IF(B5_TC03!$K$2="Blocked",1,0) -> 0 | H19: =IF(B5_TC03!$K$2="Skipped",1,0) -> 0 | I19: =IF(OR(B5_TC03!$K$2="Not Executed",B5_TC03!$K$2=""),1,0) -> 0 | J19: 1 | K19: =D19/J19 -> 1
B20: 11 | C20: B5_TC04 | D20: =IF(OR(B5_TC04!$K$2="Pass",B5_TC04!$K$2="Fail",B5_TC04!$K$2="Blocked",B5_TC04!$K$2="Skipped"),1,0) -> 1 | E20: =IF(B5_TC04!$K$2="Pass",1,0) -> 1 | F20: =IF(B5_TC04!$K$2="Fail",1,0) -> 0 | G20: =IF(B5_TC04!$K$2="Blocked",1,0) -> 0 | H20: =IF(B5_TC04!$K$2="Skipped",1,0) -> 0 | I20: =IF(OR(B5_TC04!$K$2="Not Executed",B5_TC04!$K$2=""),1,0) -> 0 | J20: 1 | K20: =D20/J20 -> 1
B21: 12 | C21: B5_TC05 | D21: =IF(OR(B5_TC05!$K$2="Pass",B5_TC05!$K$2="Fail",B5_TC05!$K$2="Blocked",B5_TC05!$K$2="Skipped"),1,0) -> 1 | E21: =IF(B5_TC05!$K$2="Pass",1,0) -> 1 | F21: =IF(B5_TC05!$K$2="Fail",1,0) -> 0 | G21: =IF(B5_TC05!$K$2="Blocked",1,0) -> 0 | H21: =IF(B5_TC05!$K$2="Skipped",1,0) -> 0 | I21: =IF(OR(B5_TC05!$K$2="Not Executed",B5_TC05!$K$2=""),1,0) -> 0 | J21: 1 | K21: =D21/J21 -> 1
B22: 13 | C22: B5_TC06 | D22: =IF(OR(B5_TC06!$K$2="Pass",B5_TC06!$K$2="Fail",B5_TC06!$K$2="Blocked",B5_TC06!$K$2="Skipped"),1,0) -> 1 | E22: =IF(B5_TC06!$K$2="Pass",1,0) -> 1 | F22: =IF(B5_TC06!$K$2="Fail",1,0) -> 0 | G22: =IF(B5_TC06!$K$2="Blocked",1,0) -> 0 | H22: =IF(B5_TC06!$K$2="Skipped",1,0) -> 0 | I22: =IF(OR(B5_TC06!$K$2="Not Executed",B5_TC06!$K$2=""),1,0) -> 0 | J22: 1 | K22: =D22/J22 -> 1
B23: 14 | C23: B5_TC07 | D23: =IF(OR(B5_TC07!$K$2="Pass",B5_TC07!$K$2="Fail",B5_TC07!$K$2="Blocked",B5_TC07!$K$2="Skipped"),1,0) -> 1 | E23: =IF(B5_TC07!$K$2="Pass",1,0) -> 1 | F23: =IF(B5_TC07!$K$2="Fail",1,0) -> 0 | G23: =IF(B5_TC07!$K$2="Blocked",1,0) -> 0 | H23: =IF(B5_TC07!$K$2="Skipped",1,0) -> 0 | I23: =IF(OR(B5_TC07!$K$2="Not Executed",B5_TC07!$K$2=""),1,0) -> 0 | J23: 1 | K23: =D23/J23 -> 1
B24: 15 | C24: B5_TC08 | D24: =IF(OR(B5_TC08!$K$2="Pass",B5_TC08!$K$2="Fail",B5_TC08!$K$2="Blocked",B5_TC08!$K$2="Skipped"),1,0) -> 1 | E24: =IF(B5_TC08!$K$2="Pass",1,0) -> 1 | F24: =IF(B5_TC08!$K$2="Fail",1,0) -> 0 | G24: =IF(B5_TC08!$K$2="Blocked",1,0) -> 0 | H24: =IF(B5_TC08!$K$2="Skipped",1,0) -> 0 | I24: =IF(OR(B5_TC08!$K$2="Not Executed",B5_TC08!$K$2=""),1,0) -> 0 | J24: 1 | K24: =D24/J24 -> 1
B25: 16 | C25: B5_TC09 | D25: =IF(OR(B5_TC09!$K$2="Pass",B5_TC09!$K$2="Fail",B5_TC09!$K$2="Blocked",B5_TC09!$K$2="Skipped"),1,0) -> 1 | E25: =IF(B5_TC09!$K$2="Pass",1,0) -> 1 | F25: =IF(B5_TC09!$K$2="Fail",1,0) -> 0 | G25: =IF(B5_TC09!$K$2="Blocked",1,0) -> 0 | H25: =IF(B5_TC09!$K$2="Skipped",1,0) -> 0 | I25: =IF(OR(B5_TC09!$K$2="Not Executed",B5_TC09!$K$2=""),1,0) -> 0 | J25: 1 | K25: =D25/J25 -> 1
B26: 17 | C26: B5_TC10 | D26: =IF(OR(B5_TC10!$K$2="Pass",B5_TC10!$K$2="Fail",B5_TC10!$K$2="Blocked",B5_TC10!$K$2="Skipped"),1,0) -> 1 | E26: =IF(B5_TC10!$K$2="Pass",1,0) -> 1 | F26: =IF(B5_TC10!$K$2="Fail",1,0) -> 0 | G26: =IF(B5_TC10!$K$2="Blocked",1,0) -> 0 | H26: =IF(B5_TC10!$K$2="Skipped",1,0) -> 0 | I26: =IF(OR(B5_TC10!$K$2="Not Executed",B5_TC10!$K$2=""),1,0) -> 0 | J26: 1 | K26: =D26/J26 -> 1
B27: 18 | C27: B5_TC11 | D27: =IF(OR(B5_TC11!$K$2="Pass",B5_TC11!$K$2="Fail",B5_TC11!$K$2="Blocked",B5_TC11!$K$2="Skipped"),1,0) -> 1 | E27: =IF(B5_TC11!$K$2="Pass",1,0) -> 1 | F27: =IF(B5_TC11!$K$2="Fail",1,0) -> 0 | G27: =IF(B5_TC11!$K$2="Blocked",1,0) -> 0 | H27: =IF(B5_TC11!$K$2="Skipped",1,0) -> 0 | I27: =IF(OR(B5_TC11!$K$2="Not Executed",B5_TC11!$K$2=""),1,0) -> 0 | J27: 1 | K27: =D27/J27 -> 1
B28: 19 | C28: B5_TC12 | D28: =IF(OR(B5_TC12!$K$2="Pass",B5_TC12!$K$2="Fail",B5_TC12!$K$2="Blocked",B5_TC12!$K$2="Skipped"),1,0) -> 1 | E28: =IF(B5_TC12!$K$2="Pass",1,0) -> 1 | F28: =IF(B5_TC12!$K$2="Fail",1,0) -> 0 | G28: =IF(B5_TC12!$K$2="Blocked",1,0) -> 0 | H28: =IF(B5_TC12!$K$2="Skipped",1,0) -> 0 | I28: =IF(OR(B5_TC12!$K$2="Not Executed",B5_TC12!$K$2=""),1,0) -> 0 | J28: 1 | K28: =D28/J28 -> 1
B29: 20 | C29: B5_TC13 | D29: =IF(OR(B5_TC13!$K$2="Pass",B5_TC13!$K$2="Fail",B5_TC13!$K$2="Blocked",B5_TC13!$K$2="Skipped"),1,0) -> 1 | E29: =IF(B5_TC13!$K$2="Pass",1,0) -> 1 | F29: =IF(B5_TC13!$K$2="Fail",1,0) -> 0 | G29: =IF(B5_TC13!$K$2="Blocked",1,0) -> 0 | H29: =IF(B5_TC13!$K$2="Skipped",1,0) -> 0 | I29: =IF(OR(B5_TC13!$K$2="Not Executed",B5_TC13!$K$2=""),1,0) -> 0 | J29: 1 | K29: =D29/J29 -> 1
B30: 21 | C30: B5_TC14 | D30: =IF(OR(B5_TC14!$K$2="Pass",B5_TC14!$K$2="Fail",B5_TC14!$K$2="Blocked",B5_TC14!$K$2="Skipped"),1,0) -> 1 | E30: =IF(B5_TC14!$K$2="Pass",1,0) -> 1 | F30: =IF(B5_TC14!$K$2="Fail",1,0) -> 0 | G30: =IF(B5_TC14!$K$2="Blocked",1,0) -> 0 | H30: =IF(B5_TC14!$K$2="Skipped",1,0) -> 0 | I30: =IF(OR(B5_TC14!$K$2="Not Executed",B5_TC14!$K$2=""),1,0) -> 0 | J30: 1 | K30: =D30/J30 -> 1
B31: 22 | C31: B5_TC15 | D31: =IF(OR(B5_TC15!$K$2="Pass",B5_TC15!$K$2="Fail",B5_TC15!$K$2="Blocked",B5_TC15!$K$2="Skipped"),1,0) -> 1 | E31: =IF(B5_TC15!$K$2="Pass",1,0) -> 1 | F31: =IF(B5_TC15!$K$2="Fail",1,0) -> 0 | G31: =IF(B5_TC15!$K$2="Blocked",1,0) -> 0 | H31: =IF(B5_TC15!$K$2="Skipped",1,0) -> 0 | I31: =IF(OR(B5_TC15!$K$2="Not Executed",B5_TC15!$K$2=""),1,0) -> 0 | J31: 1 | K31: =D31/J31 -> 1
B32: 23 | C32: B5_TC16 | D32: =IF(OR(B5_TC16!$K$2="Pass",B5_TC16!$K$2="Fail",B5_TC16!$K$2="Blocked",B5_TC16!$K$2="Skipped"),1,0) -> 1 | E32: =IF(B5_TC16!$K$2="Pass",1,0) -> 1 | F32: =IF(B5_TC16!$K$2="Fail",1,0) -> 0 | G32: =IF(B5_TC16!$K$2="Blocked",1,0) -> 0 | H32: =IF(B5_TC16!$K$2="Skipped",1,0) -> 0 | I32: =IF(OR(B5_TC16!$K$2="Not Executed",B5_TC16!$K$2=""),1,0) -> 0 | J32: 1 | K32: =D32/J32 -> 1
B33: 24 | C33: B5_TC17 | D33: =IF(OR(B5_TC17!$K$2="Pass",B5_TC17!$K$2="Fail",B5_TC17!$K$2="Blocked",B5_TC17!$K$2="Skipped"),1,0) -> 1 | E33: =IF(B5_TC17!$K$2="Pass",1,0) -> 1 | F33: =IF(B5_TC17!$K$2="Fail",1,0) -> 0 | G33: =IF(B5_TC17!$K$2="Blocked",1,0) -> 0 | H33: =IF(B5_TC17!$K$2="Skipped",1,0) -> 0 | I33: =IF(OR(B5_TC17!$K$2="Not Executed",B5_TC17!$K$2=""),1,0) -> 0 | J33: 1 | K33: =D33/J33 -> 1
B34: 25 | C34: B5_TC18 | D34: =IF(OR(B5_TC18!$K$2="Pass",B5_TC18!$K$2="Fail",B5_TC18!$K$2="Blocked",B5_TC18!$K$2="Skipped"),1,0) -> 1 | E34: =IF(B5_TC18!$K$2="Pass",1,0) -> 1 | F34: =IF(B5_TC18!$K$2="Fail",1,0) -> 0 | G34: =IF(B5_TC18!$K$2="Blocked",1,0) -> 0 | H34: =IF(B5_TC18!$K$2="Skipped",1,0) -> 0 | I34: =IF(OR(B5_TC18!$K$2="Not Executed",B5_TC18!$K$2=""),1,0) -> 0 | J34: 1 | K34: =D34/J34 -> 1
B35: 26 | C35: B5_TC19 | D35: =IF(OR(B5_TC19!$K$2="Pass",B5_TC19!$K$2="Fail",B5_TC19!$K$2="Blocked",B5_TC19!$K$2="Skipped"),1,0) -> 1 | E35: =IF(B5_TC19!$K$2="Pass",1,0) -> 1 | F35: =IF(B5_TC19!$K$2="Fail",1,0) -> 0 | G35: =IF(B5_TC19!$K$2="Blocked",1,0) -> 0 | H35: =IF(B5_TC19!$K$2="Skipped",1,0) -> 0 | I35: =IF(OR(B5_TC19!$K$2="Not Executed",B5_TC19!$K$2=""),1,0) -> 0 | J35: 1 | K35: =D35/J35 -> 1
B36: 27 | C36: B5_TC20 | D36: =IF(OR(B5_TC20!$K$2="Pass",B5_TC20!$K$2="Fail",B5_TC20!$K$2="Blocked",B5_TC20!$K$2="Skipped"),1,0) -> 1 | E36: =IF(B5_TC20!$K$2="Pass",1,0) -> 1 | F36: =IF(B5_TC20!$K$2="Fail",1,0) -> 0 | G36: =IF(B5_TC20!$K$2="Blocked",1,0) -> 0 | H36: =IF(B5_TC20!$K$2="Skipped",1,0) -> 0 | I36: =IF(OR(B5_TC20!$K$2="Not Executed",B5_TC20!$K$2=""),1,0) -> 0 | J36: 1 | K36: =D36/J36 -> 1
B37: 28 | C37: B5_TC21 | D37: =IF(OR(B5_TC21!$K$2="Pass",B5_TC21!$K$2="Fail",B5_TC21!$K$2="Blocked",B5_TC21!$K$2="Skipped"),1,0) -> 1 | E37: =IF(B5_TC21!$K$2="Pass",1,0) -> 1 | F37: =IF(B5_TC21!$K$2="Fail",1,0) -> 0 | G37: =IF(B5_TC21!$K$2="Blocked",1,0) -> 0 | H37: =IF(B5_TC21!$K$2="Skipped",1,0) -> 0 | I37: =IF(OR(B5_TC21!$K$2="Not Executed",B5_TC21!$K$2=""),1,0) -> 0 | J37: 1 | K37: =D37/J37 -> 1
B38: 29 | C38: B5_TC22 | D38: =IF(OR(B5_TC22!$K$2="Pass",B5_TC22!$K$2="Fail",B5_TC22!$K$2="Blocked",B5_TC22!$K$2="Skipped"),1,0) -> 1 | E38: =IF(B5_TC22!$K$2="Pass",1,0) -> 1 | F38: =IF(B5_TC22!$K$2="Fail",1,0) -> 0 | G38: =IF(B5_TC22!$K$2="Blocked",1,0) -> 0 | H38: =IF(B5_TC22!$K$2="Skipped",1,0) -> 0 | I38: =IF(OR(B5_TC22!$K$2="Not Executed",B5_TC22!$K$2=""),1,0) -> 0 | J38: 1 | K38: =D38/J38 -> 1
B39: 30 | C39: B5_TC23 | D39: =IF(OR(B5_TC23!$K$2="Pass",B5_TC23!$K$2="Fail",B5_TC23!$K$2="Blocked",B5_TC23!$K$2="Skipped"),1,0) -> 1 | E39: =IF(B5_TC23!$K$2="Pass",1,0) -> 1 | F39: =IF(B5_TC23!$K$2="Fail",1,0) -> 0 | G39: =IF(B5_TC23!$K$2="Blocked",1,0) -> 0 | H39: =IF(B5_TC23!$K$2="Skipped",1,0) -> 0 | I39: =IF(OR(B5_TC23!$K$2="Not Executed",B5_TC23!$K$2=""),1,0) -> 0 | J39: 1 | K39: =D39/J39 -> 1
B40: 31 | C40: B5_TC24 | D40: =IF(OR(B5_TC24!$K$2="Pass",B5_TC24!$K$2="Fail",B5_TC24!$K$2="Blocked",B5_TC24!$K$2="Skipped"),1,0) -> 1 | E40: =IF(B5_TC24!$K$2="Pass",1,0) -> 1 | F40: =IF(B5_TC24!$K$2="Fail",1,0) -> 0 | G40: =IF(B5_TC24!$K$2="Blocked",1,0) -> 0 | H40: =IF(B5_TC24!$K$2="Skipped",1,0) -> 0 | I40: =IF(OR(B5_TC24!$K$2="Not Executed",B5_TC24!$K$2=""),1,0) -> 0 | J40: 1 | K40: =D40/J40 -> 1
B41: 32 | C41: B5_TC25 | D41: =IF(OR(B5_TC25!$K$2="Pass",B5_TC25!$K$2="Fail",B5_TC25!$K$2="Blocked",B5_TC25!$K$2="Skipped"),1,0) -> 1 | E41: =IF(B5_TC25!$K$2="Pass",1,0) -> 1 | F41: =IF(B5_TC25!$K$2="Fail",1,0) -> 0 | G41: =IF(B5_TC25!$K$2="Blocked",1,0) -> 0 | H41: =IF(B5_TC25!$K$2="Skipped",1,0) -> 0 | I41: =IF(OR(B5_TC25!$K$2="Not Executed",B5_TC25!$K$2=""),1,0) -> 0 | J41: 1 | K41: =D41/J41 -> 1
B42: 33 | C42: B5_TC26 | D42: =IF(OR(B5_TC26!$K$2="Pass",B5_TC26!$K$2="Fail",B5_TC26!$K$2="Blocked",B5_TC26!$K$2="Skipped"),1,0) -> 1 | E42: =IF(B5_TC26!$K$2="Pass",1,0) -> 1 | F42: =IF(B5_TC26!$K$2="Fail",1,0) -> 0 | G42: =IF(B5_TC26!$K$2="Blocked",1,0) -> 0 | H42: =IF(B5_TC26!$K$2="Skipped",1,0) -> 0 | I42: =IF(OR(B5_TC26!$K$2="Not Executed",B5_TC26!$K$2=""),1,0) -> 0 | J42: 1 | K42: =D42/J42 -> 1
B43: 34 | C43: B5_TC27 | D43: =IF(OR(B5_TC27!$K$2="Pass",B5_TC27!$K$2="Fail",B5_TC27!$K$2="Blocked",B5_TC27!$K$2="Skipped"),1,0) -> 1 | E43: =IF(B5_TC27!$K$2="Pass",1,0) -> 1 | F43: =IF(B5_TC27!$K$2="Fail",1,0) -> 0 | G43: =IF(B5_TC27!$K$2="Blocked",1,0) -> 0 | H43: =IF(B5_TC27!$K$2="Skipped",1,0) -> 0 | I43: =IF(OR(B5_TC27!$K$2="Not Executed",B5_TC27!$K$2=""),1,0) -> 0 | J43: 1 | K43: =D43/J43 -> 1
B44: 35 | C44: B5_TC28 | D44: =IF(OR(B5_TC28!$K$2="Pass",B5_TC28!$K$2="Fail",B5_TC28!$K$2="Blocked",B5_TC28!$K$2="Skipped"),1,0) -> 1 | E44: =IF(B5_TC28!$K$2="Pass",1,0) -> 1 | F44: =IF(B5_TC28!$K$2="Fail",1,0) -> 0 | G44: =IF(B5_TC28!$K$2="Blocked",1,0) -> 0 | H44: =IF(B5_TC28!$K$2="Skipped",1,0) -> 0 | I44: =IF(OR(B5_TC28!$K$2="Not Executed",B5_TC28!$K$2=""),1,0) -> 0 | J44: 1 | K44: =D44/J44 -> 1
...

Sheet B4_TC01
A1: Test Case ID | B1: B4_TC01 | C1: Test Case Description | D1: [BÀI 4] CHILD tuổi 0 => 50 | J1: Version | K1: 2.1
A2: Created By | B2: NguyenHoTruongTam | C2: Reviewed By | D2: GVHD | J2: Test Case (Pass/Fail/Not Executed) | K2: Pass
A4: QA Tester's Log | B4: Đã review theo yêu cầu đề bài.
A6: Tester's Name | B6: NguyenHoTruongTam | C6: Date Tested | D6: 27-01-2026 | J6: Test Case
A8: S # | B8: Prerequisites: | F8: S # | G8: Test Data Requirement
A9: 1 | B9: Mở Payment Calculator | F9: 1 | G9: Age=0
A10: 2 | B10: Chọn Child | F10: 2 | G10: Type=Child
A11: 3 | B11: — | F11: 3 | G11: Click Calculate
A12: 4 | B12: — | F12: 4 | G12: Expected=50
A14: Test Conditions
A15: Step # | B15: Step Details | E15: Expected Results | H15: Actual Results | K15: Pass / Fail / Not executed / Suspended
A16: 1 | B16: Chọn Child (0-17 years). | E16: Child được chọn. | H16: Child được chọn. | K16: Pass
A17: 2 | B17: Nhập Age=0. | E17: Age hiển thị 0. | H17: Age hiển thị 0. | K17: Pass
A18: 3 | B18: Nhấn Calculate. | E18: Payment=50 euro. | H18: Payment=50 euro. | K18: Pass
A19: 4
A20: 5
A21: 6
A22: 7
A23: 8
A24: 9
A25: 10
A27: Notes | B27: Pass

Sheet B4_TC02
A1: Test Case ID | B1: B4_TC02 | C1: Test Case Description | D1: [BÀI 4] CHILD tuổi 17 (biên trên) => 50 | J1: Version | K1: 2.1
A2: Created By | B2: NguyenHoTruongTam | C2: Reviewed By | D2: GVHD | J2: Test Case (Pass/Fail/Not Executed) | K2: Pass
A4: QA Tester's Log | B4: Đã review theo yêu cầu đề bài.
A6: Tester's Name | B6: NguyenHoTruongTam | C6: Date Tested | D6: 27-01-2026 | J6: Test Case
A8: S # | B8: Prerequisites: | F8: S # | G8: Test Data Requirement
A9: 1 | B9: Mở Payment Calculator | F9: 1 | G9: Age=17
A10: 2 | B10: Chọn Child | F10: 2 | G10: Type=Child
A11: 3 | B11: — | F11: 3 | G11: Click Calculate
A12: 4 | B12: — | F12: 4 | G12: Expected=50
A14: Test Conditions
A15: Step # | B15: Step Details | E15: Expected Results | H15: Actual Results | K15: Pass / Fail / Not executed / Suspended
A16: 1 | B16: Chọn Child. | E16: Child được chọn. | H16: Child được chọn. | K16: Pass
A17: 2 | B17: Nhập Age=17. | E17: Age hiển thị 17. | H17: Age hiển thị 17. | K17: Pass
A18: 3 | B18: Nhấn Calculate. | E18: Payment=50 euro. | H18: Payment=50 euro. | K18: Pass
A19: 4
A20: 5
A21: 6
A22: 7
A23: 8
A24: 9
A25: 10
A27: Notes | B27: Pass

Sheet B4_TC03
A1: Test Case ID | B1: B4_TC03 | C1: Test Case Description | D1: [BÀI 4] MALE tuổi 18 (biên dưới) => 100 | J1: Version | K1: 2.1
A2: Created By | B2: NguyenHoTruongTam | C2: Reviewed By | D2: GVHD | J2: Test Case (Pass/Fail/Not Executed) | K2: Pass
A4: QA Tester's Log | B4: Đã review theo yêu cầu đề bài.
A6: Tester's Name | B6: NguyenHoTruongTam | C6: Date Tested | D6: 27-01-2026 | J6: Test Case
A8: S # | B8: Prerequisites: | F8: S # | G8: Test Data Requirement
A9: 1 | B9: Mở Payment Calculator | F9: 1 | G9: Age=18
A10: 2 | B10: Chọn Male | F10: 2 | G10: Type=Male
A11: 3 | B11: — | F11: 3 | G11: Click Calculate
A12: 4 | B12: — | F12: 4 | G12: Expected=100
A14: Test Conditions
A15: Step # | B15: Step Details | E15: Expected Results | H15: Actual Results | K15: Pass / Fail / Not executed / Suspended
A16: 1 | B16: Chọn Male. | E16: Male được chọn. | H16: Male được chọn. | K16: Pass
A17: 2 | B17: Nhập Age=18. | E17: Age hiển thị 18. | H17: Age hiển thị 18. | K17: Pass
A18: 3 | B18: Nhấn Calculate. | E18: Payment=100 euro. | H18: Payment=100 euro. | K18: Pass
A19: 4
A20: 5
A21: 6
A22: 7
A23: 8
A24: 9
A25: 10
A27: Notes | B27: Pass

Sheet B4_TC04
A1: Test Case ID | B1: B4_TC04 | C1: Test Case Description | D1: [BÀI 4] MALE tuổi 36 (biên dưới nhóm 2) => 120 | J1: Version | K1: 2.1
A2: Created By | B2: NguyenHoTruongTam | C2: Reviewed By | D2: GVHD | J2: Test Case (Pass/Fail/Not Executed) | K2: Pass
A4: QA Tester's Log | B4: Đã review theo yêu cầu đề bài.
A6: Tester's Name | B6: NguyenHoTruongTam | C6: Date Tested | D6: 27-01-2026 | J6: Test Case
A8: S # | B8: Prerequisites: | F8: S # | G8: Test Data Requirement
A9: 1 | B9: Mở Payment Calculator | F9: 1 | G9: Age=36
A10: 2 | B10: Chọn Male | F10: 2 | G10: Type=Male
A11: 3 | B11: — | F11: 3 | G11: Click Calculate
A12: 4 | B12: — | F12: 4 | G12: Expected=120
A14: Test Conditions
A15: Step # | B15: Step Details | E15: Expected Results | H15: Actual Results | K15: Pass / Fail / Not executed / Suspended
A16: 1 | B16: Chọn Male. | E16: Male được chọn. | H16: Male được chọn. | K16: Pass
A17: 2 | B17: Nhập Age=36. | E17: Age hiển thị 36. | H17: Age hiển thị 36. | K17: Pass
A18: 3 | B18: Nhấn Calculate. | E18: Payment=120 euro. | H18: Payment=120 euro. | K18: Pass
A19: 4
A20: 5
A21: 6
A22: 7
A23: 8
A24: 9
A25: 10
A27: Notes | B27: Pass

Sheet B4_TC05
A1: Test Case ID | B1: B4_TC05 | C1: Test Case Description | D1: [BÀI 4] FEMALE tuổi 18 => 80 | J1: Version | K1: 2.1
A2: Created By | B2: NguyenHoTruongTam | C2: Reviewed By | D2: GVHD | J2: Test Case (Pass/Fail/Not Executed) | K2: Pass
A4: QA Tester's Log | B4: Đã review theo yêu cầu đề bài.
A6: Tester's Name | B6: NguyenHoTruongTam | C6: Date Tested | D6: 27-01-2026 | J6: Test Case
A8: S # | B8: Prerequisites: | F8: S # | G8: Test Data Requirement
A9: 1 | B9: Mở Payment Calculator | F9: 1 | G9: Age=18
A10: 2 | B10: Chọn Female | F10: 2 | G10: Type=Female
A11: 3 | B11: — | F11: 3 | G11: Click Calculate
A12: 4 | B12: — | F12: 4 | G12: Expected=80
A14: Test Conditions
A15: Step # | B15: Step Details | E15: Expected Results | H15: Actual Results | K15: Pass / Fail / Not executed / Suspended
A16: 1 | B16: Chọn Female. | E16: Female được chọn. | H16: Female được chọn. | K16: Pass
A17: 2 | B17: Nhập Age=18. | E17: Age hiển thị 18. | H17: Age hiển thị 18. | K17: Pass
A18: 3 | B18: Nhấn Calculate. | E18: Payment=80 euro. | H18: Payment=80 euro. | K18: Pass
A19: 4
A20: 5
A21: 6
A22: 7
A23: 8
A24: 9
A25: 10
A27: Notes | B27: Pass

Sheet B4_TC06
A1: Test Case ID | B1: B4_TC06 | C1: Test Case Description | D1: [BÀI 4] FEMALE tuổi 50 (biên trên nhóm 2) => 110 | J1: Version | K1: 2.1
A2: Created By | B2: NguyenHoTruongTam | C2: Reviewed By | D2: GVHD | J2: Test Case (Pass/Fail/Not Executed) | K2: Pass
A4: QA Tester's Log | B4: Đã review theo yêu cầu đề bài.
A6: Tester's Name | B6: NguyenHoTruongTam | C6: Date Tested | D6: 27-01-2026 | J6: Test Case
A8: S # | B8: Prerequisites: | F8: S # | G8: Test Data Requirement
A9: 1 | B9: Mở Payment Calculator | F9: 1 | G9: Age=50
A10: 2 | B10: Chọn Female | F10: 2 | G10: Type=Female
A11: 3 | B11: — | F11: 3 | G11: Click Calculate
A12: 4 | B12: — | F12: 4 | G12: Expected=110
A14: Test Conditions
A15: Step # | B15: Step Details | E15: Expected Results | H15: Actual Results | K15: Pass / Fail / Not executed / Suspended
A16: 1 | B16: Chọn Female. | E16: Female được chọn. | H16: Female được chọn. | K16: Pass
A17: 2 | B17: Nhập Age=50. | E17: Age hiển thị 50. | H17: Age hiển thị 50. | K17: Pass
A18: 3 | B18: Nhấn Calculate. | E18: Payment=110 euro. | H18: Payment=110 euro. | K18: Pass
A19: 4
A20: 5
A21: 6
A22: 7
A23: 8
A24: 9
A25: 10
A27: Notes | B27: Pass

Sheet B4_TC07
A1: Test Case ID | B1: B4_TC07 | C1: Test Case Description | D1: [BÀI 4] Invalid age 146 => báo lỗi | J1: Version | K1: 2.1
A2: Created By | B2: NguyenHoTruongTam | C2: Reviewed By | D2: GVHD | J2: Test Case (Pass/Fail/Not Executed) | K2: Pass
A4: QA Tester's Log | B4: Đã review theo yêu cầu đề bài.
A6: Tester's Name | B6: NguyenHoTruongTam | C6: Date Tested | D6: 27-01-2026 | J6: Test Case
A8: S # | B8: Prerequisites: | F8: S # | G8: Test Data Requirement
A9: 1 | B9: Mở Payment Calculator | F9: 1 | G9: Age=146
A10: 2 | B10: Chọn Male | F10: 2 | G10: Type=Male
A11: 3 | B11: — | F11: 3 | G11: Click Calculate
A12: 4 | B12: — | F12: 4 | G12: Expected=Error
A14: Test Conditions
A15: Step # | B15: Step Details | E15: Expected Results | H15: Actual Results | K15: Pass / Fail / Not executed / Suspended
A16: 1 | B16: Chọn Male. | E16: Male được chọn. | H16: Male được chọn. | K16: Pass
A17: 2 | B17: Nhập Age=146. | E17: Age hiển thị 146. | H17: Age hiển thị 146. | K17: Pass
A18: 3 | B18: Nhấn Calculate. | E18: Thông báo lỗi tuổi không hợp lệ (>145). | H18: Thông báo lỗi tuổi không hợp lệ (>145). | K18: Pass
A19: 4
A20: 5
A21: 6
A22: 7
A23: 8
A24: 9
A25: 10
A27: Notes | B27: Pass

Sheet B5_TC01
A1: Test Case ID | B1: B5_TC01 | C1: Test Case Description | D1: [BÀI 5] Đăng ký thành công (happy path) | J1: Version | K1: 2.1
A2: Created By | B2: NguyenHoTruongTam | C2: Reviewed By | D2: GVHD | J2: Test Case (Pass/Fail/Not Executed) | K2: Pass
A4: QA Tester's Log | B4: Đã review theo yêu cầu đề bài.
A6: Tester's Name | B6: NguyenHoTruongTam | C6: Date Tested | D6: 27-01-2026 | J6: Test Case
A8: S # | B8: Prerequisites: | F8: S # | G8: Test Data Requirement
A9: 1 | B9: SQL LocalDB chạy | F9: 1 | G9: CustomerId=KH0001
A10: 2 | B10: Bảng Customers tồn tại | F10: 2 | G10: Name=Nguyễn Văn A
A11: 3 | B11: CustomerId/Email chưa tồn tại | F11: 3 | G11: Email=kh0001@email.com
A12: 4 | B12: Mở form Register | F12: 4 | G12: Phone=0912345678
A14: Test Conditions
A15: Step # | B15: Step Details | E15: Expected Results | H15: Actual Results | K15: Pass / Fail / Not executed / Suspended
A16: 1 | B16: Nhập dữ liệu hợp lệ + tick Điều khoản. | E16: Không lỗi validate. | H16: Không lỗi validate. | K16: Pass
A17: 2 | B17: Nhấn Đăng ký. | E17: Thông báo 'Đăng ký tài khoản thành công!'. | H17: Thông báo 'Đăng ký tài khoản thành công!'. | K17: Pass
A18: 3 | B18: Kiểm tra DB bằng SELECT. | E18: Có bản ghi mới (KH0001, kh0001@email.com). | H18: Có bản ghi mới (KH0001, kh0001@email.com). | K18: Pass
A19: 4
A20: 5
A21: 6
A22: 7
A23: 8
A24: 9
A25: 10
A27: Notes | B27: Pass

Sheet B5_TC02
A1: Test Case ID | B1: B5_TC02 | C1: Test Case Description | D1: [BÀI 5] CustomerId trống | J1: Version | K1: 2.1
A2: Created By | B2: NguyenHoTruongTam | C2: Reviewed By | D2: GVHD | J2: Test Case (Pass/Fail/Not Executed) | K2: Pass
A4: QA Tester's Log | B4: Đã review theo yêu cầu đề bài.
A6: Tester's Name | B6: NguyenHoTruongTam | C6: Date Tested | D6: 27-01-2026 | J6: Test Case
A8: S # | B8: Prerequisites: | F8: S # | G8: Test Data Requirement
A9: 1 | B9: Mở form Register | F9: 1 | G9: CustomerId=(blank)
A10: 2 | B10: — | F10: 2 | G10: Các trường khác hợp lệ
A11: 3 | B11: — | F11: 3 | G11: Tick Điều khoản
A12: 4 | B12: — | F12: 4 | G12: Click Đăng ký
A14: Test Conditions
A15: Step # | B15: Step Details | E15: Expected Results | H15: Actual Results | K15: Pass / Fail / Not executed / Suspended
A16: 1 | B16: Để trống Mã khách hàng. | E16: Trường CustomerId rỗng. | H16: Trường CustomerId rỗng. | K16: Pass
A17: 2 | B17: Nhấn Đăng ký. | E17: Báo lỗi: CustomerId là bắt buộc. | H17: Báo lỗi: CustomerId là bắt buộc. | K17: Pass
A18: 3
A19: 4
A20: 5
A21: 6
A22: 7
A23: 8
A24: 9
A25: 10
A27: Notes | B27: Pass

Sheet B5_TC03
A1: Test Case ID | B1: B5_TC03 | C1: Test Case Description | D1: [BÀI 5] CustomerId <6 ký tự | J1: Version | K1: 2.1
A2: Created By | B2: NguyenHoTruongTam | C2: Reviewed By | D2: GVHD | J2: Test Case (Pass/Fail/Not Executed) | K2: Pass
A4: QA Tester's Log | B4: Đã review theo yêu cầu đề bài.
A6: Tester's Name | B6: NguyenHoTruongTam | C6: Date Tested | D6: 27-01-2026 | J6: Test Case
A8: S # | B8: Prerequisites: | F8: S # | G8: Test Data Requirement
A9: 1 | B9: Mở form Register | F9: 1 | G9: CustomerId=KH1
A10: 2 | B10: — | F10: 2 | G10: Các trường khác hợp lệ
A11: 3 | B11: — | F11: 3 | G11: Tick Điều khoản
A12: 4 | B12: — | F12: 4 | G12: Click Đăng ký
A14: Test Conditions
A15: Step # | B15: Step Details | E15: Expected Results | H15: Actual Results | K15: Pass / Fail / Not executed / Suspended
A16: 1 | B16: Nhập CustomerId=KH1. | E16: Độ dài <6. | H16: Độ dài <6. | K16: Pass
A17: 2 | B17: Nhấn Đăng ký. | E17: Báo lỗi: CustomerId 6-10 ký tự. | H17: Báo lỗi: CustomerId 6-10 ký tự. | K17: Pass
A18: 3
A19: 4
A20: 5
A21: 6
A22: 7
A23: 8
A24: 9
A25: 10
A27: Notes | B27: Pass

Sheet B5_TC04
A1: Test Case ID | B1: B5_TC04 | C1: Test Case Description | D1: [BÀI 5] CustomerId chứa ký tự đặc biệt | J1: Version | K1: 2.1
A2: Created By | B2: NguyenHoTruongTam | C2: Reviewed By | D2: GVHD | J2: Test Case (Pass/Fail/Not Executed) | K2: Pass
A4: QA Tester's Log | B4: Đã review theo yêu cầu đề bài.
A6: Tester's Name | B6: NguyenHoTruongTam | C6: Date Tested | D6: 27-01-2026 | J6: Test Case
A8: S # | B8: Prerequisites: | F8: S # | G8: Test Data Requirement
A9: 1 | B9: Mở form Register | F9: 1 | G9: CustomerId=KH@001
A10: 2 | B10: — | F10: 2 | G10: Các trường khác hợp lệ
A11: 3 | B11: — | F11: 3 | G11: Tick Điều khoản
A12: 4 | B12: — | F12: 4 | G12: Click Đăng ký
A14: Test Conditions
A15: Step # | B15: Step Details | E15: Expected Results | H15: Actual Results | K15: Pass / Fail / Not executed / Suspended
A16: 1 | B16: Nhập CustomerId=KH@001. | E16: Có ký tự @. | H16: Có ký tự @. | K16: Pass
A17: 2 | B17: Nhấn Đăng ký. | E17: Báo lỗi: chỉ cho phép chữ và số. | H17: Báo lỗi: chỉ cho phép chữ và số. | K17: Pass
A18: 3
A19: 4
A20: 5
A21: 6
A22: 7
A23: 8
A24: 9
A25: 10
A27: Notes | B27: Pass

Sheet B5_TC05
A1: Test Case ID | B1: B5_TC05 | C1: Test Case Description | D1: [BÀI 5] CustomerId trùng lặp | J1: Version | K1: 2.1
A2: Created By | B2: NguyenHoTruongTam | C2: Reviewed By | D2: GVHD | J2: Test Case (Pass/Fail/Not Executed) | K2: Pass
A4: QA Tester's Log | B4: Đã review theo yêu cầu đề bài.
A6: Tester's Name | B6: NguyenHoTruongTam | C6: Date Tested | D6: 27-01-2026 | J6: Test Case
A8: S # | B8: Prerequisites: | F8: S # | G8: Test Data Requirement
A9: 1 | B9: DB có CustomerId=KH0002 | F9: 1 | G9: CustomerId=KH0002
A10: 2 | B10: Mở form Register | F10: 2 | G10: Email=kh0002_new@email.com
A11: 3 | B11: — | F11: 3 | G11: Phone=0912345678
A12: 4 | B12: — | F12: 4 | G12: Tick Điều khoản
A14: Test Conditions
A15: Step # | B15: Step Details | E15: Expected Results | H15: Actual Results | K15: Pass / Fail / Not executed / Suspended
A16: 1 | B16: Nhập CustomerId đã tồn tại. | E16: CustomerId=KH0002. | H16: CustomerId=KH0002. | K16: Pass
A17: 2 | B17: Nhấn Đăng ký. | E17: Báo lỗi: CustomerId đã tồn tại. | H17: Báo lỗi: CustomerId đã tồn tại. | K17: Pass
A18: 3
A19: 4
A20: 5
A21: 6
A22: 7
A23: 8
A24: 9
A25: 10
A27: Notes | B27: Pass

Sheet B5_TC06
A1: Test Case ID | B1: B5_TC06 | C1: Test Case Description | D1: [BÀI 5] Email sai định dạng | J1: Version | K1: 2.1
A2: Created By | B2: NguyenHoTruongTam | C2: Reviewed By | D2: GVHD | J2: Test Case (Pass/Fail/Not Executed) | K2: Pass
A4: QA Tester's Log | B4: Đã review theo yêu cầu đề bài.
A6: Tester's Name | B6: NguyenHoTruongTam | C6: Date Tested | D6: 27-01-2026 | J6: Test Case
A8: S # | B8: Prerequisites: | F8: S # | G8: Test Data Requirement
A9: 1 | B9: Mở form Register | F9: 1 | G9: Email=abc@
A10: 2 | B10: — | F10: 2 | G10: Các trường khác hợp lệ
A11: 3 | B11: — | F11: 3 | G11: Tick Điều khoản
A12: 4 | B12: — | F12: 4 | G12: Click Đăng ký
A14: Test Conditions
A15: Step # | B15: Step Details | E15: Expected Results | H15: Actual Results | K15: Pass / Fail / Not executed / Suspended
A16: 1 | B16: Nhập Email=abc@ | E16: Sai định dạng. | H16: Sai định dạng. | K16: Pass
A17: 2 | B17: Nhấn Đăng ký. | E17: Báo lỗi: Email không hợp lệ. | H17: Báo lỗi: Email không hợp lệ. | K17: Pass
A18: 3
A19: 4
A20: 5
A21: 6
A22: 7
A23: 8
A24: 9
A25: 10
A27: Notes | B27: Pass

Sheet B5_TC07
A1: Test Case ID | B1: B5_TC07 | C1: Test Case Description | D1: [BÀI 5] Email trùng lặp | J1: Version | K1: 2.1
A2: Created By | B2: NguyenHoTruongTam | C2: Reviewed By | D2: GVHD | J2: Test Case (Pass/Fail/Not Executed) | K2: Pass
A4: QA Tester's Log | B4: Đã review theo yêu cầu đề bài.
A6: Tester's Name | B6: NguyenHoTruongTam | C6: Date Tested | D6: 27-01-2026 | J6: Test Case
A8: S # | B8: Prerequisites: | F8: S # | G8: Test Data Requirement
A9: 1 | B9: DB có Email=dup@email.com | F9: 1 | G9: Email=dup@email.com
A10: 2 | B10: Mở form Register | F10: 2 | G10: CustomerId=KH0099
A11: 3 | B11: — | F11: 3 | G11: Phone=0912345678
A12: 4 | B12: — | F12: 4 | G12: Tick Điều khoản
A14: Test Conditions
A15: Step # | B15: Step Details | E15: Expected Results | H15: Actual Results | K15: Pass / Fail / Not executed / Suspended
A16: 1 | B16: Nhập Email đã tồn tại. | E16: Email=dup@email.com. | H16: Email=dup@email.com. | K16: Pass
A17: 2 | B17: Nhấn Đăng ký. | E17: Báo lỗi: Email đã tồn tại. | H17: Báo lỗi: Email đã tồn tại. | K17: Pass
A18: 3
A19: 4
A20: 5
A21: 6
A22: 7
A23: 8
A24: 9
A25: 10
A27: Notes | B27: Pass

Sheet B5_TC08
A1: Test Case ID | B1: B5_TC08 | C1: Test Case Description | D1: [BÀI 5] SĐT không bắt đầu bằng 0 | J1: Version | K1: 2.1
A2: Created By | B2: NguyenHoTruongTam | C2: Reviewed By | D2: GVHD | J2: Test Case (Pass/Fail/Not Executed) | K2: Pass
A4: QA Tester's Log | B4: Đã review theo yêu cầu đề bài.
A6: Tester's Name | B6: NguyenHoTruongTam | C6: Date Tested | D6: 27-01-2026 | J6: Test Case
A8: S # | B8: Prerequisites: | F8: S # | G8: Test Data Requirement
A9: 1 | B9: Mở form Register | F9: 1 | G9: Phone=9123456789
A10: 2 | B10: — | F10: 2 | G10: Các trường khác hợp lệ
A11: 3 | B11: — | F11: 3 | G11: Tick Điều khoản
A12: 4 | B12: — | F12: 4 | G12: Click Đăng ký
A14: Test Conditions
A15: Step # | B15: Step Details | E15: Expected Results | H15: Actual Results | K15: Pass / Fail / Not executed / Suspended
A16: 1 | B16: Nhập SĐT=9123456789. | E16: Không bắt đầu bằng 0. | H16: Không bắt đầu bằng 0. | K16: Pass
A17: 2 | B17: Nhấn Đăng ký. | E17: Báo lỗi: SĐT phải bắt đầu bằng 0. | H17: Báo lỗi: SĐT phải bắt đầu bằng 0. | K17: Pass
A18: 3
A19: 4
A20: 5
A21: 6
A22: 7
A23: 8
A24: 9
A25: 10
A27: Notes | B27: Pass

Sheet B5_TC09
A1: Test Case ID | B1: B5_TC09 | C1: Test Case Description | D1: [BÀI 5] Xác nhận mật khẩu không khớp | J1: Version | K1: 2.1
A2: Created By | B2: NguyenHoTruongTam | C2: Reviewed By | D2: GVHD | J2: Test Case (Pass/Fail/Not Executed) | K2: Pass
A4: QA Tester's Log | B4: Đã review theo yêu cầu đề bài.
A6: Tester's Name | B6: NguyenHoTruongTam | C6: Date Tested | D6: 27-01-2026 | J6: Test Case
A8: S # | B8: Prerequisites: | F8: S # | G8: Test Data Requirement
A9: 1 | B9: Mở form Register | F9: 1 | G9: Password=abc12345
A10: 2 | B10: — | F10: 2 | G10: Confirm=abc12346
A11: 3 | B11: — | F11: 3 | G11: Các trường khác hợp lệ
A12: 4 | B12: — | F12: 4 | G12: Tick Điều khoản
A14: Test Conditions
A15: Step # | B15: Step Details | E15: Expected Results | H15: Actual Results | K15: Pass / Fail / Not executed / Suspended
A16: 1 | B16: Nhập Password và Confirm khác nhau. | E16: Password!=Confirm. | H16: Password!=Confirm. | K16: Pass
A17: 2 | B17: Nhấn Đăng ký. | E17: Báo lỗi: Xác nhận mật khẩu không khớp. | H17: Báo lỗi: Xác nhận mật khẩu không khớp. | K17: Pass
A18: 3 | K18: Pass
A19: 4 | K19: Pass
A20: 5 | K20: Pass
A21: 6 | K21: Pass
A22: 7 | K22: Pass
A23: 8 | K23: Pass
A24: 9 | K24: Pass
A25: 10 | K25: Pass
A27: Notes | B27: Pass

Sheet B5_TC10
A1: Test Case ID | B1: B5_TC10 | C1: Test Case Description | D1: [BÀI 5] Không tick điều khoản dịch vụ | J1: Version | K1: 2.1
A2: Created By | B2: NguyenHoTruongTam | C2: Reviewed By | D2: GVHD | J2: Test Case (Pass/Fail/Not Executed) | K2: Pass
A4: QA Tester's Log | B4: Đã review theo yêu cầu đề bài.
A6: Tester's Name | B6: NguyenHoTruongTam | C6: Date Tested | D6: 27-01-2026 | J6: Test Case
A8: S # | B8: Prerequisites: | F8: S # | G8: Test Data Requirement
A9: 1 | B9: Mở form Register | F9: 1 | G9: Tất cả dữ liệu hợp lệ
A10: 2 | B10: — | F10: 2 | G10: Terms=unchecked
A11: 3 | B11: — | F11: 3 | G11: Click Đăng ký
A12: 4 | B12: — | F12: 4 | G12: —
A14: Test Conditions
A15: Step # | B15: Step Details | E15: Expected Results | H15: Actual Results | K15: Pass / Fail / Not executed / Suspended
A16: 1 | B16: Nhập dữ liệu hợp lệ nhưng không tick điều khoản. | E16: Terms=false. | H16: Terms=false. | K16: Pass
A17: 2 | B17: Nhấn Đăng ký. | E17: Báo lỗi: phải đồng ý điều khoản. | H17: Báo lỗi: phải đồng ý điều khoản. | K17: Pass
A18: 3
A19: 4
A20: 5
A21: 6
A22: 7
A23: 8
A24: 9
A25: 10
A27: Notes | B27: Pass

Sheet B5_TC11
A1: Test Case ID | B1: B5_TC01 | C1: B5_011 | D1: [BÀI 5] Đăng ký thành công (happy path) | J1: Version | K1: 2.1
A2: Created By | B2: NguyenHoTruongTam | C2: Reviewed By | D2: GVHD | J2: Test Case (Pass/Fail/Not Executed) | K2: Pass
A4: QA Tester's Log | B4: Đã review theo yêu cầu đề bài.
A6: Tester's Name | B6: NguyenHoTruongTam | C6: Date Tested | D6: 27-01-2026 | J6: Test Case
A8: S # | B8: Prerequisites: | F8: S # | G8: Test Data Requirement
A9: 1 | B9: Mở ứng dụng RegisterForm | F9: 1 | G9: MaKH: '' (rỗng)
A10: 2 | B10: Kết nối DB LocalDB (Bai5_Register_SQL) | F10: 2 | G10: Các trường khác hợp lệ
A11: 3 | B11: Bảng Customers/KhachHang tồn tại | F11: 3 | G11: Tick điều khoản
A12: 4 | B12: Form đang ở trạng thái rỗng
A14: Test Conditions
A15: Step # | B15: Step Details | E15: Expected Results | H15: Actual Results | K15: Pass / Fail / Not executed / Suspended
A16: 1 | B16: Nhập dữ liệu theo Test Data | E16: Các trường nhận dữ liệu đúng (theo mô tả) | H16: Các trường nhận dữ liệu đúng (theo mô tả) | K16: Pass
A17: 2 | B17: Nhấn nút 'Đăng ký' | E17: Hệ thống thực hiện validate toàn bộ trường | H17: Hệ thống thực hiện validate toàn bộ trường | K17: Pass
A18: 3 | B18: Quan sát thông báo/hiển thị lỗi | E18: Hiển thị lỗi 'Mã khách hàng là bắt buộc' | H18: Hiển thị lỗi 'Mã khách hàng là bắt buộc' | K18: Pass
A23: 8
A24: 9
A25: 10
A27: Notes | B27: Pass

Sheet B5_TC12
A1: Test Case ID | B1: B5_TC01 | C1: B5_012 | D1: [BÀI 5] Đăng ký thành công (happy path) | J1: Version | K1: 2.1
A2: Created By | B2: NguyenHoTruongTam | C2: Reviewed By | D2: GVHD | J2: Test Case (Pass/Fail/Not Executed) | K2: Pass
A4: QA Tester's Log | B4: Đã review theo yêu cầu đề bài.
A6: Tester's Name | B6: NguyenHoTruongTam | C6: Date Tested | D6: 27-01-2026 | J6: Test Case
A8: S # | B8: Prerequisites: | F8: S # | G8: Test Data Requirement
A9: 1 | B9: Mở ứng dụng RegisterForm | F9: 1 | G9: MaKH: 'A1234' (5 ký tự)
A10: 2 | B10: Kết nối DB LocalDB (Bai5_Register_SQL)
A11: 3 | B11: Bảng Customers/KhachHang tồn tại
A12: 4 | B12: Form đang ở trạng thái rỗng
A14: Test Conditions
A15: Step # | B15: Step Details | E15: Expected Results | H15: Actual Results | K15: Pass / Fail / Not executed / Suspended
A16: 1 | B16: Nhập dữ liệu theo Test Data | E16: Các trường nhận dữ liệu đúng (theo mô tả) | H16: Các trường nhận dữ liệu đúng (theo mô tả) | K16: Pass
A17: 2 | B17: Nhấn nút 'Đăng ký' | E17: Hệ thống thực hiện validate toàn bộ trường | H17: Hệ thống thực hiện validate toàn bộ trường | K17: Pass
A18: 3 | B18: Quan sát thông báo/hiển thị lỗi | E18: Hiển thị lỗi độ dài 6-10 | H18: Hiển thị lỗi độ dài 6-10 | K18: Pass
A23: 8
A24: 9
A25: 10
A27: Notes | B27: Pass

Sheet B5_TC13
A1: Test Case ID | B1: B5_TC01 | C1: B5_013 | D1: [BÀI 5] Đăng ký thành công (happy path) | J1: Version | K1: 2.1
A2: Created By | B2: NguyenHoTruongTam | C2: Reviewed By | D2: GVHD | J2: Test Case (Pass/Fail/Not Executed) | K2: Pass
A4: QA Tester's Log | B4: Đã review theo yêu cầu đề bài.
A6: Tester's Name | B6: NguyenHoTruongTam | C6: Date Tested | D6: 27-01-2026 | J6: Test Case
A8: S # | B8: Prerequisites: | F8: S # | G8: Test Data Requirement
A9: 1 | B9: Mở ứng dụng RegisterForm | F9: 1 | G9: MaKH: 'ABC12345678' (11 ký tự)
A10: 2 | B10: Kết nối DB LocalDB (Bai5_Register_SQL)
A11: 3 | B11: Bảng Customers/KhachHang tồn tại
A12: 4 | B12: Form đang ở trạng thái rỗng
A14: Test Conditions
A15: Step # | B15: Step Details | E15: Expected Results | H15: Actual Results | K15: Pass / Fail / Not executed / Suspended
A16: 1 | B16: Nhập dữ liệu theo Test Data | E16: Các trường nhận dữ liệu đúng (theo mô tả) | H16: Các trường nhận dữ liệu đúng (theo mô tả) | K16: Pass
A17: 2 | B17: Nhấn nút 'Đăng ký' | E17: Hệ thống thực hiện validate toàn bộ trường | H17: Hệ thống thực hiện validate toàn bộ trường | K17: Pass
A18: 3 | B18: Quan sát thông báo/hiển thị lỗi | E18: Hiển thị lỗi độ dài 6-10 | H18: Hiển thị lỗi độ dài 6-10 | K18: Pass
A23: 8
A24: 9
A25: 10
A27: Notes | B27: Pass

Sheet B5_TC14
A1: Test Case ID | B1: B5_TC01 | C1: B5_014 | D1: [BÀI 5] Đăng ký thành công (happy path) | J1: Version | K1: 2.1
A2: Created By | B2: NguyenHoTruongTam | C2: Reviewed By | D2: GVHD | J2: Test Case (Pass/Fail/Not Executed) | K2: Pass
A4: QA Tester's Log | B4: Đã review theo yêu cầu đề bài.
A6: Tester's Name | B6: NguyenHoTruongTam | C6: Date Tested | D6: 27-01-2026 | J6: Test Case
A8: S # | B8: Prerequisites: | F8: S # | G8: Test Data Requirement
A9: 1 | B9: Mở ứng dụng RegisterForm | F9: 1 | G9: MaKH: 'KH@123'
A10: 2 | B10: Kết nối DB LocalDB (Bai5_Register_SQL)
A11: 3 | B11: Bảng Customers/KhachHang tồn tại
A12: 4 | B12: Form đang ở trạng thái rỗng
A14: Test Conditions
A15: Step # | B15: Step Details | E15: Expected Results | H15: Actual Results | K15: Pass / Fail / Not executed / Suspended
A16: 1 | B16: Nhập dữ liệu theo Test Data | E16: Các trường nhận dữ liệu đúng (theo mô tả) | H16: Các trường nhận dữ liệu đúng (theo mô tả) | K16: Pass
A17: 2 | B17: Nhấn nút 'Đăng ký' | E17: Hệ thống thực hiện validate toàn bộ trường | H17: Hệ thống thực hiện validate toàn bộ trường | K17: Pass
A18: 3 | B18: Quan sát thông báo/hiển thị lỗi | E18: Hiển thị lỗi chỉ chữ và số | H18: Hiển thị lỗi chỉ chữ và số | K18: Pass
A23: 8
A24: 9
A25: 10
A27: Notes | B27: Pass

Sheet B5_TC15
A1: Test Case ID | B1: B5_TC01 | C1: B5_015 | D1: [BÀI 5] Đăng ký thành công (happy path) | J1: Version | K1: 2.1
A2: Created By | B2: NguyenHoTruongTam | C2: Reviewed By | D2: GVHD | J2: Test Case (Pass/Fail/Not Executed) | K2: Pass
A4: QA Tester's Log | B4: Đã review theo yêu cầu đề bài.
A6: Tester's Name | B6: NguyenHoTruongTam | C6: Date Tested | D6: 27-01-2026 | J6: Test Case
A8: S # | B8: Prerequisites: | F8: S # | G8: Test Data Requirement
A9: 1 | B9: Mở ứng dụng RegisterForm | F9: 1 | G9: MaKH: 'KH0001' đã có trong DB
A10: 2 | B10: Kết nối DB LocalDB (Bai5_Register_SQL)
A11: 3 | B11: Bảng Customers/KhachHang tồn tại
A12: 4 | B12: Form đang ở trạng thái rỗng
A14: Test Conditions
A15: Step # | B15: Step Details | E15: Expected Results | H15: Actual Results | K15: Pass / Fail / Not executed / Suspended
A16: 1 | B16: Nhập dữ liệu theo Test Data | E16: Các trường nhận dữ liệu đúng (theo mô tả) | H16: Các trường nhận dữ liệu đúng (theo mô tả) | K16: Pass
A17: 2 | B17: Nhấn nút 'Đăng ký' | E17: Hệ thống thực hiện validate toàn bộ trường | H17: Hệ thống thực hiện validate toàn bộ trường | K17: Pass
A18: 3 | B18: Quan sát thông báo/hiển thị lỗi | E18: Hiển thị lỗi 'Mã khách hàng đã tồn tại' | H18: Hiển thị lỗi 'Mã khách hàng đã tồn tại' | K18: Pass
A23: 8
A24: 9
A25: 10
A27: Notes | B27: Pass

Sheet B5_TC16
A1: Test Case ID | B1: B5_TC01 | C1: B5_016 | D1: [BÀI 5] Đăng ký thành công (happy path) | J1: Version | K1: 2.1
A2: Created By | B2: NguyenHoTruongTam | C2: Reviewed By | D2: GVHD | J2: Test Case (Pass/Fail/Not Executed) | K2: Pass
A4: QA Tester's Log | B4: Đã review theo yêu cầu đề bài.
A6: Tester's Name | B6: NguyenHoTruongTam | C6: Date Tested | D6: 27-01-2026 | J6: Test Case
A8: S # | B8: Prerequisites: | F8: S # | G8: Test Data Requirement
A9: 1 | B9: Mở ứng dụng RegisterForm | F9: 1 | G9: HoTen: ''
A10: 2 | B10: Kết nối DB LocalDB (Bai5_Register_SQL)
A11: 3 | B11: Bảng Customers/KhachHang tồn tại
A12: 4 | B12: Form đang ở trạng thái rỗng
A14: Test Conditions
A15: Step # | B15: Step Details | E15: Expected Results | H15: Actual Results | K15: Pass / Fail / Not executed / Suspended
A16: 1 | B16: Nhập dữ liệu theo Test Data | E16: Các trường nhận dữ liệu đúng (theo mô tả) | H16: Các trường nhận dữ liệu đúng (theo mô tả) | K16: Pass
A17: 2 | B17: Nhấn nút 'Đăng ký' | E17: Hệ thống thực hiện validate toàn bộ trường | H17: Hệ thống thực hiện validate toàn bộ trường | K17: Pass
A18: 3 | B18: Quan sát thông báo/hiển thị lỗi | E18: Hiển thị lỗi 'Họ và tên là bắt buộc' | H18: Hiển thị lỗi 'Họ và tên là bắt buộc' | K18: Pass
A23: 8
A24: 9
A25: 10
A27: Notes | B27: Pass

Sheet B5_TC17
A1: Test Case ID | B1: B5_TC01 | C1: B5_017 | D1: [BÀI 5] Đăng ký thành công (happy path) | J1: Version | K1: 2.1
A2: Created By | B2: NguyenHoTruongTam | C2: Reviewed By | D2: GVHD | J2: Test Case (Pass/Fail/Not Executed) | K2: Pass
A4: QA Tester's Log | B4: Đã review theo yêu cầu đề bài.
A6: Tester's Name | B6: NguyenHoTruongTam | C6: Date Tested | D6: 27-01-2026 | J6: Test Case
A8: S # | B8: Prerequisites: | F8: S # | G8: Test Data Requirement
A9: 1 | B9: Mở ứng dụng RegisterForm | F9: 1 | G9: HoTen: 'An A' (4 ký tự tính cả khoảng trắng?)
A10: 2 | B10: Kết nối DB LocalDB (Bai5_Register_SQL)
A11: 3 | B11: Bảng Customers/KhachHang tồn tại
A12: 4 | B12: Form đang ở trạng thái rỗng
A14: Test Conditions
A15: Step # | B15: Step Details | E15: Expected Results | H15: Actual Results | K15: Pass / Fail / Not executed / Suspended
A16: 1 | B16: Nhập dữ liệu theo Test Data | E16: Các trường nhận dữ liệu đúng (theo mô tả) | H16: Các trường nhận dữ liệu đúng (theo mô tả) | K16: Pass
A17: 2 | B17: Nhấn nút 'Đăng ký' | E17: Hệ thống thực hiện validate toàn bộ trường | H17: Hệ thống thực hiện validate toàn bộ trường | K17: Pass
A18: 3 | B18: Quan sát thông báo/hiển thị lỗi | E18: Hiển thị lỗi độ dài 5-50 | H18: Hiển thị lỗi độ dài 5-50 | K18: Pass
A23: 8
A24: 9
A25: 10
A27: Notes | B27: Pass

Sheet B5_TC18
A1: Test Case ID | B1: B5_TC01 | C1: B5_018 | D1: [BÀI 5] Đăng ký thành công (happy path) | J1: Version | K1: 2.1
A2: Created By | B2: NguyenHoTruongTam | C2: Reviewed By | D2: GVHD | J2: Test Case (Pass/Fail/Not Executed) | K2: Pass
A4: QA Tester's Log | B4: Đã review theo yêu cầu đề bài.
A6: Tester's Name | B6: NguyenHoTruongTam | C6: Date Tested | D6: 27-01-2026 | J6: Test Case
A8: S # | B8: Prerequisites: | F8: S # | G8: Test Data Requirement
A9: 1 | B9: Mở ứng dụng RegisterForm | F9: 1 | G9: HoTen: 51 ký tự
A10: 2 | B10: Kết nối DB LocalDB (Bai5_Register_SQL)
A11: 3 | B11: Bảng Customers/KhachHang tồn tại
A12: 4 | B12: Form đang ở trạng thái rỗng
A14: Test Conditions
A15: Step # | B15: Step Details | E15: Expected Results | H15: Actual Results | K15: Pass / Fail / Not executed / Suspended
A16: 1 | B16: Nhập dữ liệu theo Test Data | E16: Các trường nhận dữ liệu đúng (theo mô tả) | H16: Các trường nhận dữ liệu đúng (theo mô tả) | K16: Pass
A17: 2 | B17: Nhấn nút 'Đăng ký' | E17: Hệ thống thực hiện validate toàn bộ trường | H17: Hệ thống thực hiện validate toàn bộ trường | K17: Pass
A18: 3 | B18: Quan sát thông báo/hiển thị lỗi | E18: Hiển thị lỗi độ dài 5-50 | H18: Hiển thị lỗi độ dài 5-50 | K18: Pass
A23: 8
A24: 9
A25: 10
A27: Notes | B27: Pass

Sheet B5_TC19
A1: Test Case ID | B1: B5_TC01 | C1: B5_019 | D1: [BÀI 5] Đăng ký thành công (happy path) | J1: Version | K1: 2.1
A2: Created By | B2: NguyenHoTruongTam | C2: Reviewed By | D2: GVHD | J2: Test Case (Pass/Fail/Not Executed) | K2: Pass
A4: QA Tester's Log | B4: Đã review theo yêu cầu đề bài.
A6: Tester's Name | B6: NguyenHoTruongTam | C6: Date Tested | D6: 27-01-2026 | J6: Test Case
A8: S # | B8: Prerequisites: | F8: S # | G8: Test Data Requirement
A9: 1 | B9: Mở ứng dụng RegisterForm | F9: 1 | G9: HoTen: 'Nguyen Van A1'
A10: 2 | B10: Kết nối DB LocalDB (Bai5_Register_SQL)
A11: 3 | B11: Bảng Customers/KhachHang tồn tại
A12: 4 | B12: Form đang ở trạng thái rỗng
A14: Test Conditions
A15: Step # | B15: Step Details | E15: Expected Results | H15: Actual Results | K15: Pass / Fail / Not executed / Suspended
A16: 1 | B16: Nhập dữ liệu theo Test Data | E16: Các trường nhận dữ liệu đúng (theo mô tả) | H16: Các trường nhận dữ liệu đúng (theo mô tả) | K16: Pass
A17: 2 | B17: Nhấn nút 'Đăng ký' | E17: Hệ thống thực hiện validate toàn bộ trường | H17: Hệ thống thực hiện validate toàn bộ trường | K17: Pass
A18: 3 | B18: Quan sát thông báo/hiển thị lỗi | E18: Hiển thị lỗi chỉ chữ + khoảng trắng | H18: Hiển thị lỗi chỉ chữ + khoảng trắng | K18: Pass
A23: 8
A24: 9
A25: 10
A27: Notes | B27: Pass

Sheet B5_TC20
A1: Test Case ID | B1: B5_TC01 | C1: B5_020 | D1: [BÀI 5] Đăng ký thành công (happy path) | J1: Version | K1: 2.1
A2: Created By | B2: NguyenHoTruongTam | C2: Reviewed By | D2: GVHD | J2: Test Case (Pass/Fail/Not Executed) | K2: Pass
A4: QA Tester's Log | B4: Đã review theo yêu cầu đề bài.
A6: Tester's Name | B6: NguyenHoTruongTam | C6: Date Tested | D6: 27-01-2026 | J6: Test Case
A8: S # | B8: Prerequisites: | F8: S # | G8: Test Data Requirement
A9: 1 | B9: Mở ứng dụng RegisterForm | F9: 1 | G9: Email: ''
A10: 2 | B10: Kết nối DB LocalDB (Bai5_Register_SQL)
A11: 3 | B11: Bảng Customers/KhachHang tồn tại
A12: 4 | B12: Form đang ở trạng thái rỗng
A14: Test Conditions
A15: Step # | B15: Step Details | E15: Expected Results | H15: Actual Results | K15: Pass / Fail / Not executed / Suspended
A16: 1 | B16: Nhập dữ liệu theo Test Data | E16: Các trường nhận dữ liệu đúng (theo mô tả) | H16: Các trường nhận dữ liệu đúng (theo mô tả) | K16: Pass
A17: 2 | B17: Nhấn nút 'Đăng ký' | E17: Hệ thống thực hiện validate toàn bộ trường | H17: Hệ thống thực hiện validate toàn bộ trường | K17: Pass
A18: 3 | B18: Quan sát thông báo/hiển thị lỗi | E18: Hiển thị lỗi 'Email là bắt buộc' | H18: Hiển thị lỗi 'Email là bắt buộc' | K18: Pass
A23: 8
A24: 9
A25: 10
A27: Notes | B27: Pass

Sheet B5_TC21
A1: Test Case ID | B1: B5_TC01 | C1: B5_021 | D1: [BÀI 5] Đăng ký thành công (happy path) | J1: Version | K1: 2.1
A2: Created By | B2: NguyenHoTruongTam | C2: Reviewed By | D2: GVHD | J2: Test Case (Pass/Fail/Not Executed) | K2: Pass
A4: QA Tester's Log | B4: Đã review theo yêu cầu đề bài.
A6: Tester's Name | B6: NguyenHoTruongTam | C6: Date Tested | D6: 27-01-2026 | J6: Test Case
A8: S # | B8: Prerequisites: | F8: S # | G8: Test Data Requirement
A9: 1 | B9: Mở ứng dụng RegisterForm | F9: 1 | G9: Email: 'abc@'
A10: 2 | B10: Kết nối DB LocalDB (Bai5_Register_SQL)
A11: 3 | B11: Bảng Customers/KhachHang tồn tại
A12: 4 | B12: Form đang ở trạng thái rỗng
A14: Test Conditions
A15: Step # | B15: Step Details | E15: Expected Results | H15: Actual Results | K15: Pass / Fail / Not executed / Suspended
A16: 1 | B16: Nhập dữ liệu theo Test Data | E16: Các trường nhận dữ liệu đúng (theo mô tả) | H16: Các trường nhận dữ liệu đúng (theo mô tả) | K16: Pass
A17: 2 | B17: Nhấn nút 'Đăng ký' | E17: Hệ thống thực hiện validate toàn bộ trường | H17: Hệ thống thực hiện validate toàn bộ trường | K17: Pass
A18: 3 | B18: Quan sát thông báo/hiển thị lỗi | E18: Hiển thị lỗi 'Email không hợp lệ' | H18: Hiển thị lỗi 'Email không hợp lệ' | K18: Pass
A23: 8
A24: 9
A25: 10
A27: Notes | B27: Pass

Sheet B5_TC22
A1: Test Case ID | B1: B5_TC01 | C1: B5_022 | D1: [BÀI 5] Đăng ký thành công (happy path) | J1: Version | K1: 2.1
A2: Created By | B2: NguyenHoTruongTam | C2: Reviewed By | D2: GVHD | J2: Test Case (Pass/Fail/Not Executed) | K2: Pass
A4: QA Tester's Log | B4: Đã review theo yêu cầu đề bài.
A6: Tester's Name | B6: NguyenHoTruongTam | C6: Date Tested | D6: 27-01-2026 | J6: Test Case
A8: S # | B8: Prerequisites: | F8: S # | G8: Test Data Requirement
A9: 1 | B9: Mở ứng dụng RegisterForm | F9: 1 | G9: Email: 'a@b.com' đã có trong DB
A10: 2 | B10: Kết nối DB LocalDB (Bai5_Register_SQL)
A11: 3 | B11: Bảng Customers/KhachHang tồn tại
A12: 4 | B12: Form đang ở trạng thái rỗng
A14: Test Conditions
A15: Step # | B15: Step Details | E15: Expected Results | H15: Actual Results | K15: Pass / Fail / Not executed / Suspended
A16: 1 | B16: Nhập dữ liệu theo Test Data | E16: Các trường nhận dữ liệu đúng (theo mô tả) | H16: Các trường nhận dữ liệu đúng (theo mô tả) | K16: Pass
A17: 2 | B17: Nhấn nút 'Đăng ký' | E17: Hệ thống thực hiện validate toàn bộ trường | H17: Hệ thống thực hiện validate toàn bộ trường | K17: Pass
A18: 3 | B18: Quan sát thông báo/hiển thị lỗi | E18: Hiển thị lỗi 'Email đã tồn tại' | H18: Hiển thị lỗi 'Email đã tồn tại' | K18: Pass
A23: 8
A24: 9
A25: 10
A27: Notes | B27: Pass

Sheet B5_TC23
A1: Test Case ID | B1: B5_TC01 | C1: B5_023 | D1: [BÀI 5] Đăng ký thành công (happy path) | J1: Version | K1: 2.1
A2: Created By | B2: NguyenHoTruongTam | C2: Reviewed By | D2: GVHD | J2: Test Case (Pass/Fail/Not Executed) | K2: Pass
A4: QA Tester's Log | B4: Đã review theo yêu cầu đề bài.
A6: Tester's Name | B6: NguyenHoTruongTam | C6: Date Tested | D6: 27-01-2026 | J6: Test Case
A8: S # | B8: Prerequisites: | F8: S # | G8: Test Data Requirement
A9: 1 | B9: Mở ứng dụng RegisterForm | F9: 1 | G9: SDT: ''
A10: 2 | B10: Kết nối DB LocalDB (Bai5_Register_SQL)
A11: 3 | B11: Bảng Customers/KhachHang tồn tại
A12: 4 | B12: Form đang ở trạng thái rỗng
A14: Test Conditions
A15: Step # | B15: Step Details | E15: Expected Results | H15: Actual Results | K15: Pass / Fail / Not executed / Suspended
A16: 1 | B16: Nhập dữ liệu theo Test Data | E16: Các trường nhận dữ liệu đúng (theo mô tả) | H16: Các trường nhận dữ liệu đúng (theo mô tả) | K16: Pass
A17: 2 | B17: Nhấn nút 'Đăng ký' | E17: Hệ thống thực hiện validate toàn bộ trường | H17: Hệ thống thực hiện validate toàn bộ trường | K17: Pass
A18: 3 | B18: Quan sát thông báo/hiển thị lỗi | E18: Hiển thị lỗi 'Số điện thoại là bắt buộc' | H18: Hiển thị lỗi 'Số điện thoại là bắt buộc' | K18: Pass
A23: 8
A24: 9
A25: 10
A27: Notes | B27: Pass

Sheet B5_TC24
A1: Test Case ID | B1: B5_TC01 | C1: B5_024 | D1: [BÀI 5] Đăng ký thành công (happy path) | J1: Version | K1: 2.1
A2: Created By | B2: NguyenHoTruongTam | C2: Reviewed By | D2: GVHD | J2: Test Case (Pass/Fail/Not Executed) | K2: Pass
A4: QA Tester's Log | B4: Đã review theo yêu cầu đề bài.
A6: Tester's Name | B6: NguyenHoTruongTam | C6: Date Tested | D6: 27-01-2026 | J6: Test Case
A8: S # | B8: Prerequisites: | F8: S # | G8: Test Data Requirement
A9: 1 | B9: Mở ứng dụng RegisterForm | F9: 1 | G9: SDT: '09A1234567'
A10: 2 | B10: Kết nối DB LocalDB (Bai5_Register_SQL)
A11: 3 | B11: Bảng Customers/KhachHang tồn tại
A12: 4 | B12: Form đang ở trạng thái rỗng
A14: Test Conditions
A15: Step # | B15: Step Details | E15: Expected Results | H15: Actual Results | K15: Pass / Fail / Not executed / Suspended
A16: 1 | B16: Nhập dữ liệu theo Test Data | E16: Các trường nhận dữ liệu đúng (theo mô tả) | H16: Các trường nhận dữ liệu đúng (theo mô tả) | K16: Pass
A17: 2 | B17: Nhấn nút 'Đăng ký' | E17: Hệ thống thực hiện validate toàn bộ trường | H17: Hệ thống thực hiện validate toàn bộ trường | K17: Pass
A18: 3 | B18: Quan sát thông báo/hiển thị lỗi | E18: Hiển thị lỗi chỉ cho nhập số | H18: Hiển thị lỗi chỉ cho nhập số | K18: Pass
A23: 8
A24: 9
A25: 10
A27: Notes | B27: Pass

Sheet B5_TC25
A1: Test Case ID | B1: B5_TC01 | C1: B5_025 | D1: [BÀI 5] Đăng ký thành công (happy path) | J1: Version | K1: 2.1
A2: Created By | B2: NguyenHoTruongTam | C2: Reviewed By | D2: GVHD | J2: Test Case (Pass/Fail/Not Executed) | K2: Pass
A4: QA Tester's Log | B4: Đã review theo yêu cầu đề bài.
A6: Tester's Name | B6: NguyenHoTruongTam | C6: Date Tested | D6: 27-01-2026 | J6: Test Case
A8: S # | B8: Prerequisites: | F8: S # | G8: Test Data Requirement
A9: 1 | B9: Mở ứng dụng RegisterForm | F9: 1 | G9: SDT: '091234567' (9 số)
A10: 2 | B10: Kết nối DB LocalDB (Bai5_Register_SQL)
A11: 3 | B11: Bảng Customers/KhachHang tồn tại
A12: 4 | B12: Form đang ở trạng thái rỗng
A14: Test Conditions
A15: Step # | B15: Step Details | E15: Expected Results | H15: Actual Results | K15: Pass / Fail / Not executed / Suspended
A16: 1 | B16: Nhập dữ liệu theo Test Data | E16: Các trường nhận dữ liệu đúng (theo mô tả) | H16: Các trường nhận dữ liệu đúng (theo mô tả) | K16: Pass
A17: 2 | B17: Nhấn nút 'Đăng ký' | E17: Hệ thống thực hiện validate toàn bộ trường | H17: Hệ thống thực hiện validate toàn bộ trường | K17: Pass
A18: 3 | B18: Quan sát thông báo/hiển thị lỗi | E18: Hiển thị lỗi 10-12 số | H18: Hiển thị lỗi 10-12 số | K18: Pass
A23: 8
A24: 9
A25: 10
A27: Notes | B27: Pass

Sheet B5_TC26
A1: Test Case ID | B1: B5_TC01 | C1: B5_026 | D1: [BÀI 5] Đăng ký thành công (happy path) | J1: Version | K1: 2.1
A2: Created By | B2: NguyenHoTruongTam | C2: Reviewed By | D2: GVHD | J2: Test Case (Pass/Fail/Not Executed) | K2: Pass
A4: QA Tester's Log | B4: Đã review theo yêu cầu đề bài.
A6: Tester's Name | B6: NguyenHoTruongTam | C6: Date Tested | D6: 27-01-2026 | J6: Test Case
A8: S # | B8: Prerequisites: | F8: S # | G8: Test Data Requirement
A9: 1 | B9: Mở ứng dụng RegisterForm | F9: 1 | G9: SDT: '0912345678901' (13 số)
A10: 2 | B10: Kết nối DB LocalDB (Bai5_Register_SQL)
A11: 3 | B11: Bảng Customers/KhachHang tồn tại
A12: 4 | B12: Form đang ở trạng thái rỗng
A14: Test Conditions
A15: Step # | B15: Step Details | E15: Expected Results | H15: Actual Results | K15: Pass / Fail / Not executed / Suspended
A16: 1 | B16: Nhập dữ liệu theo Test Data | E16: Các trường nhận dữ liệu đúng (theo mô tả) | H16: Các trường nhận dữ liệu đúng (theo mô tả) | K16: Pass
A17: 2 | B17: Nhấn nút 'Đăng ký' | E17: Hệ thống thực hiện validate toàn bộ trường | H17: Hệ thống thực hiện validate toàn bộ trường | K17: Pass
A18: 3 | B18: Quan sát thông báo/hiển thị lỗi | E18: Hiển thị lỗi 10-12 số | H18: Hiển thị lỗi 10-12 số | K18: Pass
A23: 8
A24: 9
A25: 10
A27: Notes | B27: Pass

Sheet B5_TC27
A1: Test Case ID | B1: B5_TC01 | C1: B5_027 | D1: [BÀI 5] Đăng ký thành công (happy path) | J1: Version | K1: 2.1
A2: Created By | B2: NguyenHoTruongTam | C2: Reviewed By | D2: GVHD | J2: Test Case (Pass/Fail/Not Executed) | K2: Pass
A4: QA Tester's Log | B4: Đã review theo yêu cầu đề bài.
A6: Tester's Name | B6: NguyenHoTruongTam | C6: Date Tested | D6: 27-01-2026 | J6: Test Case
A8: S # | B8: Prerequisites: | F8: S # | G8: Test Data Requirement
A9: 1 | B9: Mở ứng dụng RegisterForm | F9: 1 | G9: SDT: '1912345678'
A10: 2 | B10: Kết nối DB LocalDB (Bai5_Register_SQL)
A11: 3 | B11: Bảng Customers/KhachHang tồn tại
A12: 4 | B12: Form đang ở trạng thái rỗng
A14: Test Conditions
A15: Step # | B15: Step Details | E15: Expected Results | H15: Actual Results | K15: Pass / Fail / Not executed / Suspended
A16: 1 | B16: Nhập dữ liệu theo Test Data | E16: Các trường nhận dữ liệu đúng (theo mô tả) | H16: Các trường nhận dữ liệu đúng (theo mô tả) | K16: Pass
A17: 2 | B17: Nhấn nút 'Đăng ký' | E17: Hệ thống thực hiện validate toàn bộ trường | H17: Hệ thống thực hiện validate toàn bộ trường | K17: Pass
A18: 3 | B18: Quan sát thông báo/hiển thị lỗi | E18: Hiển thị lỗi phải bắt đầu bằng 0 | H18: Hiển thị lỗi phải bắt đầu bằng 0 | K18: Pass
A23: 8
A24: 9
A25: 10
A27: Notes | B27: Pass

Sheet B5_TC28
A1: Test Case ID | B1: B5_TC01 | C1: B5_028 | D1: [BÀI 5] Đăng ký thành công (happy path) | J1: Version | K1: 2.1
A2: Created By | B2: NguyenHoTruongTam | C2: Reviewed By | D2: GVHD | J2: Test Case (Pass/Fail/Not Executed) | K2: Pass
A4: QA Tester's Log | B4: Đã review theo yêu cầu đề bài.
A6: Tester's Name | B6: NguyenHoTruongTam | C6: Date Tested | D6: 27-01-2026 | J6: Test Case
A8: S # | B8: Prerequisites: | F8: S # | G8: Test Data Requirement
A9: 1 | B9: Mở ứng dụng RegisterForm | F9: 1 | G9: DiaChi: ''
A10: 2 | B10: Kết nối DB LocalDB (Bai5_Register_SQL)
A11: 3 | B11: Bảng Customers/KhachHang tồn tại
A12: 4 | B12: Form đang ở trạng thái rỗng
A14: Test Conditions
A15: Step # | B15: Step Details | E15: Expected Results | H15: Actual Results | K15: Pass / Fail / Not executed / Suspended
A16: 1 | B16: Nhập dữ liệu theo Test Data | E16: Các trường nhận dữ liệu đúng (theo mô tả) | H16: Các trường nhận dữ liệu đúng (theo mô tả) | K16: Pass
A17: 2 | B17: Nhấn nút 'Đăng ký' | E17: Hệ thống thực hiện validate toàn bộ trường | H17: Hệ thống thực hiện validate toàn bộ trường | K17: Pass
A18: 3 | B18: Quan sát thông báo/hiển thị lỗi | E18: Hiển thị lỗi 'Địa chỉ là bắt buộc' | H18: Hiển thị lỗi 'Địa chỉ là bắt buộc' | K18: Pass
A23: 8
A24: 9
A25: 10
A27: Notes | B27: Pass

Sheet B5_TC29
A1: Test Case ID | B1: B5_TC01 | C1: B5_029 | D1: [BÀI 5] Đăng ký thành công (happy path) | J1: Version | K1: 2.1
A2: Created By | B2: NguyenHoTruongTam | C2: Reviewed By | D2: GVHD | J2: Test Case (Pass/Fail/Not Executed) | K2: Pass
A4: QA Tester's Log | B4: Đã review theo yêu cầu đề bài.
A6: Tester's Name | B6: NguyenHoTruongTam | C6: Date Tested | D6: 27-01-2026 | J6: Test Case
A8: S # | B8: Prerequisites: | F8: S # | G8: Test Data Requirement
A9: 1 | B9: Mở ứng dụng RegisterForm | F9: 1 | G9: DiaChi: 256 ký tự
A10: 2 | B10: Kết nối DB LocalDB (Bai5_Register_SQL)
A11: 3 | B11: Bảng Customers/KhachHang tồn tại
A12: 4 | B12: Form đang ở trạng thái rỗng
A14: Test Conditions
A15: Step # | B15: Step Details | E15: Expected Results | H15: Actual Results | K15: Pass / Fail / Not executed / Suspended
A16: 1 | B16: Nhập dữ liệu theo Test Data | E16: Các trường nhận dữ liệu đúng (theo mô tả) | H16: Các trường nhận dữ liệu đúng (theo mô tả) | K16: Pass
A17: 2 | B17: Nhấn nút 'Đăng ký' | E17: Hệ thống thực hiện validate toàn bộ trường | H17: Hệ thống thực hiện validate toàn bộ trường | K17: Pass
A18: 3 | B18: Quan sát thông báo/hiển thị lỗi | E18: Hiển thị lỗi tối đa 255 ký tự | H18: Hiển thị lỗi tối đa 255 ký tự | K18: Pass
A23: 8
A24: 9
A25: 10
A27: Notes | B27: Pass

Sheet B5_TC30
A1: Test Case ID | B1: B5_TC01 | C1: B5_030 | D1: [BÀI 5] Đăng ký thành công (happy path) | J1: Version | K1: 2.1
A2: Created By | B2: NguyenHoTruongTam | C2: Reviewed By | D2: GVHD | J2: Test Case (Pass/Fail/Not Executed) | K2: Pass
A4: QA Tester's Log | B4: Đã review theo yêu cầu đề bài.
A6: Tester's Name | B6: NguyenHoTruongTam | C6: Date Tested | D6: 27-01-2026 | J6: Test Case
A8: S # | B8: Prerequisites: | F8: S # | G8: Test Data Requirement
A9: 1 | B9: Mở ứng dụng RegisterForm | F9: 1 | G9: MatKhau: '1234567' (7 ký tự)
A10: 2 | B10: Kết nối DB LocalDB (Bai5_Register_SQL)
A11: 3 | B11: Bảng Customers/KhachHang tồn tại
A12: 4 | B12: Form đang ở trạng thái rỗng
A14: Test Conditions
A15: Step # | B15: Step Details | E15: Expected Results | H15: Actual Results | K15: Pass / Fail / Not executed / Suspended
